Workbook

Sheet MVP

Sheet Target Date
A1: BDC ROLL-OUT PLAN
A2: Division | B2: Target Date | C2: Scope/Activity | D2: Remarks
A3: Head Office | B3: May 6-10 | C3: Initial deployment, configuration, and validation of biometric data consolidation | D3: Priority users and key departments will be tested first
A4: Ware House | B4: May 11-15 | C4: Deployment to warehouse biometric devices and validation of data syncing | D4: Confirm device connectivity and successful data transfer
A5: Retail Operations | B5: May 16 onwards | C5: Pilot rollout to 100 selected stores with stable internet connectivity | D5: Pilot results will be monitored before full store-wide rollout
A6: Remaining Stores | B6: After successful pilot | C6: Gradual rollout to the remaining stores | D6: Proceed only if no major issues are encountered during the pilot phase
A8: Note:
A9: Full rollout to the remaining stores will proceed after the pilot implementation is validated and no major system, connectivity, or data synchronization issues are identified.
A10: This rollout covers the basic version of the Biometric Data Consolidator Project. After the successful implementation and validation of the basic version, the development of the complete version with additional features and enhancements will begin.

Sheet Stores
A1: System Name | B1: Store Name | C1: Tag | D1: Telco | E1: Biometric Device Brand/Model | F1: Serial Number | G1: IP Address | H1: Rollout Phase
A2: ZHNG | B2: Hinunangan Leyte-FS | C2: Opened Stores | D2: -
A3: ZLSK | B3: Lebak Sultan Kudarat-FS | C3: Opened Stores | D3: -
A4: ZLIL | B4: Liloan Leyte - FS | C4: Opened Stores | D4: -
A5: ONEA | B5: One Ayala | C5: Opened Stores | D5: -
A6: ZCBI | B6: Caibiran Biliran-FS | C6: Opened Stores | D6: -
A7: SMAZ | B7: SM Hypermarket Alabang Zaporte Road | C7: Opened Stores | D7: -
A8: WTCT | B8: Waltermart Concepcion Tarlac | C8: Opened Stores | D8: -
A9: ZLTP | B9: Lantapan Bukidnon-FS | C9: Opened Stores | D9: -
A10: ZKSK | B10: Kalamansig Sultan Kudarat-FS | C10: Opened Stores | D10: -
A11: ZLAK | B11: Laak Commercial Bgld FS | C11: Opened Stores | D11: -
A12: CMAB | B12: Citymall Anabu | C12: Opened Stores | D12: -
A13: ZBDN | B13: Bindoy Negros Oriental-FS | C13: Opened Stores | D13: -
... A19: PIT2 | B19: Paranaque Integrated Terminal Exchange 2 | C19: Opened Stores | D19: -
A20: SGMM | B20: Southgate Mall Makati | C20: Opened Stores | D20: - | E20: ZKTECO | F20: CQUJ233561279 | G20: 192.168.1.201
A21: ZTUA | B21: Tuao Cagayan Valley-FS | C21: Opened Stores | D21: -
A22: ZWAO | B22: Wao Lanao del Sur-FS | C22: Opened Stores | D22: -
A23: TQSM | B23: The Square Mall 2 | C23: Opened Stores | D23: -
A24: ZBNC | B24: Banisilan Cotabato-FS | C24: Opened Stores | D24: -
A25: ZKLC | B25: Kalilangan Centro-FS | C25: Opened Stores | D25: -
A26: SMCD | B26: SM City Daet | C26: Opened Stores | D26: -
A27: SMHI | B27: SM Hypermarket Iloilo | C27: Opened Stores | D27: -
A28: ZBGB | B28: Baungon Bukidnon-FS | C28: Opened Stores | D28: -
A29: AY30 | B29: Ayala Malls The 30th | C29: Opened Stores | D29: - | E29: ZKTECO | F29: AEYU082360215 | G29: 192.168.1.201
A30: ZOES | B30: Oras Eastern Samar-FS | C30: Opened Stores | D30: -
A31: ZSBS | B31: Saint Bernard Southern Leyte-FS | C31: Opened Stores | D31: -
A32: ZBSD | B32: Baloc Sto. Domingo Nueva Ecija-FS | C32: - | D32: -
B33: SM City Puerto Princesa | C33: - | D33: -
A34: ZAFM | B34: AS Fortuna Mandaue-FS | C34: - | D34: -
B35: Red Square Bagbaguin | C35: - | D35: -
B36: SM City Sto. Tomas Batangas | C36: - | D36: -
A37: VSTS | B37: Victory Central Mall Sta. Rosa | C37: Opened Stores | D37: -
A38: LKKC | B38: Limketkai Center | C38: Opened Stores | D38: -
A39: MSMT | B39: Massway Mall Tanay | C39: Opened Stores | D39: - | E39: ZKTECO | F39: ZKM6251700027 | G39: 192.168.1.201
A40: ZLBS | B40: Lamitan Basilan-FS | C40: Opened Stores | D40: -
A41: GSBT | B41: Gaisano Butuan | C41: Opened Stores | D41: -
A42: ZJNO | B42: Jimalalud Negros Oriental-FS | C42: Opened Stores | D42: -
A43: ZCRC | B43: Caramoan Camarines Sur-FS | C43: Opened Stores | D43: -
A44: SMSG | B44: SM Sangandaan | C44: Incoming Stores | D44: -
A45: PMGL | B45: Primark Gilmar | C45: Incoming Stores | D45: -
...

Sheet Roll Out Phase Per Store
A1: Division | B1: Code | C1: Name | D1: Location | E1: Cluster | F1: Contact Person | G1: Contact Number | H1: Tag | I1: Telco | J1: Biometric Device Brand/Model | K1: Serial Number | L1: IP Address | M1: Rollout Phase
A2: RTM Operations | B2: NN044 | C2: 999C | D2: 999 Caloocan | E2: NCR North & East | H2: =VLOOKUP(C2,Stores!$A$200:$G$1118,3,0) -> Opened Stores | I2: =VLOOKUP(C2,Stores!$A$200:$G$1118,4,0) -> Stage 7 - Installed | J2: =VLOOKUP(C2,Stores!$A$200:$G$1118,5,0) -> ZKTECO | K2: =VLOOKUP(C2,Stores!$A$200:$G$1118,6,0) -> AKDG012351682 | L2: =VLOOKUP(C2,Stores!$A$200:$G$1118,7,0) -> 192.168.1.201 | M2: Phase 1
A3: RTM Operations | B3: NN037 | C3: ABTC | D3: Zabarte Town Center | E3: NCR North & East | H3: =VLOOKUP(C3,Stores!$A$200:$G$1118,3,0) -> Opened Stores | I3: =VLOOKUP(C3,Stores!$A$200:$G$1118,4,0) -> Stage 7 - Installed | J3: =VLOOKUP(C3,Stores!$A$200:$G$1118,5,0) -> FINGERTEC | K3: =VLOOKUP(C3,Stores!$A$200:$G$1118,6,0) -> 7425858 | L3: =VLOOKUP(C3,Stores!$A$200:$G$1118,7,0) -> 192.168.1.201 | M3: Phase 1
A4: RTM Operations | B4: NN004 | C4: AFLZ | D4: Ayala Feliz | E4: NCR North & East | H4: =VLOOKUP(C4,Stores!$A$200:$G$1118,3,0) -> Opened Stores | I4: =VLOOKUP(C4,Stores!$A$200:$G$1118,4,0) -> Stage 7 - Installed | J4: =VLOOKUP(C4,Stores!$A$200:$G$1118,5,0) -> FINGERTEC | K4: =VLOOKUP(C4,Stores!$A$200:$G$1118,6,0) -> 7417213 | L4: =VLOOKUP(C4,Stores!$A$200:$G$1118,7,0) -> 192.168.1.201 | M4: Phase 1
A5: RTM Operations | B5: NN010 | C5: AFVT | D5: Ayala Fairview Terraces | E5: NCR North & East | H5: =VLOOKUP(C5,Stores!$A$200:$G$1118,3,0) -> Opened Stores | I5: =VLOOKUP(C5,Stores!$A$200:$G$1118,4,0) -> Stage 7 - Installed | J5: =VLOOKUP(C5,Stores!$A$200:$G$1118,5,0) -> FINGERTEC | K5: =VLOOKUP(C5,Stores!$A$200:$G$1118,6,0) -> 7417485 | L5: =VLOOKUP(C5,Stores!$A$200:$G$1118,7,0) -> 192.168.1.201 | M5: Phase 1
A6: RTM Operations | B6: NN085 | C6: ALIM | D6: Ali Mall | E6: NCR North & East | H6: =VLOOKUP(C6,Stores!$A$200:$G$1118,3,0) -> Opened Stores | I6: =VLOOKUP(C6,Stores!$A$200:$G$1118,4,0) -> Stage 7 - Installed | J6: =VLOOKUP(C6,Stores!$A$200:$G$1118,5,0) -> ZKTECO | K6: =VLOOKUP(C6,Stores!$A$200:$G$1118,6,0) -> PAS4252900187 | L6: =VLOOKUP(C6,Stores!$A$200:$G$1118,7,0) -> 192.168.1.201 | M6: Phase 1
A7: RTM Operations | B7: NN006 | C7: AMRK | D7: Ayala Marikina | E7: NCR North & East | H7: =VLOOKUP(C7,Stores!$A$200:$G$1118,3,0) -> Opened Stores | I7: =VLOOKUP(C7,Stores!$A$200:$G$1118,4,0) -> Stage 7 - Installed | J7: =VLOOKUP(C7,Stores!$A$200:$G$1118,5,0) -> ZKTECO | K7: =VLOOKUP(C7,Stores!$A$200:$G$1118,6,0) -> ZKM6245100263 | L7: =VLOOKUP(C7,Stores!$A$200:$G$1118,7,0) -> 192.168.201 | M7: Phase 1
A8: RTM Operations | B8: CG059 | C8: ARDM | D8: Ardi Mall | E8: NCR North & East | H8: =VLOOKUP(C8,Stores!$A$200:$G$1118,3,0) -> Opened Stores | I8: =VLOOKUP(C8,Stores!$A$200:$G$1118,4,0) -> Stage 7 - Installed | J8: =VLOOKUP(C8,Stores!$A$200:$G$1118,5,0) -> ZKTECO | K8: =VLOOKUP(C8,Stores!$A$200:$G$1118,6,0) -> ABN5221960318 | L8: =VLOOKUP(C8,Stores!$A$200:$G$1118,7,0) -> 192.168.1.201 | M8: Phase 1
A9: RTM Operations | B9: NN058 | C9: AYCL | D9: Ayala Cloverleaf | E9: NCR North & East | H9: =VLOOKUP(C9,Stores!$A$200:$G$1118,3,0) -> Opened Stores | I9: =VLOOKUP(C9,Stores!$A$200:$G$1118,4,0) -> Stage 7 - Installed | J9: =VLOOKUP(C9,Stores!$A$200:$G$1118,5,0) -> ZKTECO | K9: =VLOOKUP(C9,Stores!$A$200:$G$1118,6,0) -> AEYU082360228 | L9: =VLOOKUP(C9,Stores!$A$200:$G$1118,7,0) -> 192.168.1.201 | M9: Phase 1
A10: RTM Operations | B10: NN009 | C10: BWMQ | D10: Bluewave Marquinton | E10: NCR North & East | H10: =VLOOKUP(C10,Stores!$A$200:$G$1118,3,0) -> Opened Stores | I10: =VLOOKUP(C10,Stores!$A$200:$G$1118,4,0) -> Stage 7 - Installed | J10: =VLOOKUP(C10,Stores!$A$200:$G$1118,5,0) -> FINGERTEC | K10: =VLOOKUP(C10,Stores!$A$200:$G$1118,6,0) -> 7417201 | L10: =VLOOKUP(C10,Stores!$A$200:$G$1118,7,0) -> 192.168.1.201 | M10: Phase 1
A11: RTM Operations | B11: CG032 | C11: CATP | D11: SM Cherry Antipolo | E11: NCR North & East | H11: =VLOOKUP(C11,Stores!$A$200:$G$1118,3,0) -> Opened Stores | I11: =VLOOKUP(C11,Stores!$A$200:$G$1118,4,0) -> Stage 7 - Installed | J11: =VLOOKUP(C11,Stores!$A$200:$G$1118,5,0) -> FINGERTEC | K11: =VLOOKUP(C11,Stores!$A$200:$G$1118,6,0) -> 7423721 | L11: =VLOOKUP(C11,Stores!$A$200:$G$1118,7,0) -> 192.168.1.201 | M11: Phase 1
A12: RTM Operations | B12: NN012 | C12: CCLC | D12: Circle C | E12: NCR North & East | H12: =VLOOKUP(C12,Stores!$A$200:$G$1118,3,0) -> Opened Stores | I12: =VLOOKUP(C12,Stores!$A$200:$G$1118,4,0) -> Stage 7 - Installed | J12: =VLOOKUP(C12,Stores!$A$200:$G$1118,5,0) -> FINGERTEC | K12: =VLOOKUP(C12,Stores!$A$200:$G$1118,6,0) -> 7419182 | L12: =VLOOKUP(C12,Stores!$A$200:$G$1118,7,0) -> 192.168.1.201 | M12: Phase 1
A13: RTM Operations | B13: NN026 | C13: CFDC | D13: Cherry Foodarama Congressional | E13: NCR North & East | H13: =VLOOKUP(C13,Stores!$A$200:$G$1118,3,0) -> Opened Stores | I13: =VLOOKUP(C13,Stores!$A$200:$G$1118,4,0) -> Stage 7 - Installed | J13: =VLOOKUP(C13,Stores!$A$200:$G$1118,5,0) -> FINGERTEC | K13: =VLOOKUP(C13,Stores!$A$200:$G$1118,6,0) -> 7425874 | L13: =VLOOKUP(C13,Stores!$A$200:$G$1118,7,0) -> 192.168.1.201 | M13: Phase 1
... A101: RTM Operations | B101: NN071 | C101: ZSMD | D101: Suki Market Dapitan - FS | E101: NCR North & East | H101: =VLOOKUP(C101,Stores!$A$200:$G$1118,3,0) -> Opened Stores | I101: =VLOOKUP(C101,Stores!$A$200:$G$1118,4,0) -> Stage 7 - Installed | J101: =VLOOKUP(C101,Stores!$A$200:$G$1118,5,0) -> ZKTECO | K101: =VLOOKUP(C101,Stores!$A$200:$G$1118,6,0) -> CQUJ233560029 | L101: =VLOOKUP(C101,Stores!$A$200:$G$1118,7,0) -> 192.168.1.201 | M101: Phase 1
A102: RTM Operations | B102: MS037 | C102: ZBNC | D102: Banisilan Cotabato-FS | E102: Mindanao 1 | F102: Michael Sambuat | G102: 9658455599 | H102: =VLOOKUP(C102,Stores!$A$200:$G$1118,3,0) -> #N/A | I102: =VLOOKUP(C102,Stores!$A$200:$G$1118,4,0) -> #N/A | J102: =VLOOKUP(C102,Stores!$A$200:$G$1118,5,0) -> #N/A | K102: =VLOOKUP(C102,Stores!$A$200:$G$1118,6,0) -> #N/A | L102: =VLOOKUP(C102,Stores!$A$200:$G$1118,7,0) -> #N/A | M102: Phase 10
A103: RTM Operations | B103: MD060 | C103: ZCD2 | D103: Calinan Davao City 2-FS | E103: Mindanao 1 | F103: April Caga-anan | G103: 9171894643 | H103: =VLOOKUP(C103,Stores!$A$200:$G$1118,3,0) -> #N/A | I103: =VLOOKUP(C103,Stores!$A$200:$G$1118,4,0) -> #N/A | J103: =VLOOKUP(C103,Stores!$A$200:$G$1118,5,0) -> #N/A | K103: =VLOOKUP(C103,Stores!$A$200:$G$1118,6,0) -> #N/A | L103: =VLOOKUP(C103,Stores!$A$200:$G$1118,7,0) -> #N/A | M103: Phase 10
A104: RTM Operations | B104: MT007 | C104: ZDDO | D104: Dalican Maguindanao-FS | E104: Mindanao 1 | F104: Reynand John Cabanalan | G104: 9702517040 | H104: =VLOOKUP(C104,Stores!$A$200:$G$1118,3,0) -> #N/A | I104: =VLOOKUP(C104,Stores!$A$200:$G$1118,4,0) -> #N/A | J104: =VLOOKUP(C104,Stores!$A$200:$G$1118,5,0) -> #N/A | K104: =VLOOKUP(C104,Stores!$A$200:$G$1118,6,0) -> #N/A | L104: =VLOOKUP(C104,Stores!$A$200:$G$1118,7,0) -> #N/A | M104: Phase 10
A105: RTM Operations | B105: MS031 | C105: ZKSK | D105: Kalamansig Sultan Kudarat-FS | E105: Mindanao 1 | F105: Richard Gepilga | G105: 9088671744 | H105: =VLOOKUP(C105,Stores!$A$200:$G$1118,3,0) -> #N/A | I105: =VLOOKUP(C105,Stores!$A$200:$G$1118,4,0) -> #N/A | J105: =VLOOKUP(C105,Stores!$A$200:$G$1118,5,0) -> #N/A | K105: =VLOOKUP(C105,Stores!$A$200:$G$1118,6,0) -> #N/A | L105: =VLOOKUP(C105,Stores!$A$200:$G$1118,7,0) -> #N/A | M105: Phase 10
A106: RTM Operations | B106: MD044 | C106: ZLAK | D106: Laak Commercial Building - FS | E106: Mindanao 1 | F106: Marlon Peral | G106: 9763291296 | H106: =VLOOKUP(C106,Stores!$A$200:$G$1118,3,0) -> #N/A | I106: =VLOOKUP(C106,Stores!$A$200:$G$1118,4,0) -> #N/A | J106: =VLOOKUP(C106,Stores!$A$200:$G$1118,5,0) -> #N/A | K106: =VLOOKUP(C106,Stores!$A$200:$G$1118,6,0) -> #N/A | L106: =VLOOKUP(C106,Stores!$A$200:$G$1118,7,0) -> #N/A | M106: Phase 10
A107: RTM Operations | B107: MS019 | C107: ZLSK | D107: Lebak Sultan Kudarat-FS | E107: Mindanao 1 | F107: Richard Gepilga | G107: 9088671744 | H107: =VLOOKUP(C107,Stores!$A$200:$G$1118,3,0) -> #N/A | I107: =VLOOKUP(C107,Stores!$A$200:$G$1118,4,0) -> #N/A | J107: =VLOOKUP(C107,Stores!$A$200:$G$1118,5,0) -> #N/A | K107: =VLOOKUP(C107,Stores!$A$200:$G$1118,6,0) -> #N/A | L107: =VLOOKUP(C107,Stores!$A$200:$G$1118,7,0) -> #N/A | M107: Phase 10
A108: RTM Operations | B108: MS042 | C108: ZMKL | D108: Makilala North Cotabato-FS | E108: Mindanao 1 | F108: MARY JANE SOLIS | G108: 9190065781 | H108: =VLOOKUP(C108,Stores!$A$200:$G$1118,3,0) -> #N/A | I108: =VLOOKUP(C108,Stores!$A$200:$G$1118,4,0) -> #N/A | J108: =VLOOKUP(C108,Stores!$A$200:$G$1118,5,0) -> #N/A | K108: =VLOOKUP(C108,Stores!$A$200:$G$1118,6,0) -> #N/A | L108: =VLOOKUP(C108,Stores!$A$200:$G$1118,7,0) -> #N/A | M108: Phase 10
A109: RTM Operations | B109: MD043 | C109: ZSAM | D109: Santa Maria Davao Occidental - FS | E109: Mindanao 1 | F109: Gregie Benlot | G109: 9209473589 | H109: =VLOOKUP(C109,Stores!$A$200:$G$1118,3,0) -> #N/A | I109: =VLOOKUP(C109,Stores!$A$200:$G$1118,4,0) -> #N/A | J109: =VLOOKUP(C109,Stores!$A$200:$G$1118,5,0) -> #N/A | K109: =VLOOKUP(C109,Stores!$A$200:$G$1118,6,0) -> #N/A | L109: =VLOOKUP(C109,Stores!$A$200:$G$1118,7,0) -> #N/A | M109: Phase 10
A110: RTM Operations | B110: MD059 | C110: ZSMT | D110: San Miguel Tagum-FS | E110: Mindanao 1 | F110: Chady Gellido | G110: 9171610089 | H110: =VLOOKUP(C110,Stores!$A$200:$G$1118,3,0) -> #N/A | I110: =VLOOKUP(C110,Stores!$A$200:$G$1118,4,0) -> #N/A | J110: =VLOOKUP(C110,Stores!$A$200:$G$1118,5,0) -> #N/A | K110: =VLOOKUP(C110,Stores!$A$200:$G$1118,6,0) -> #N/A | L110: =VLOOKUP(C110,Stores!$A$200:$G$1118,7,0) -> #N/A | M110: Phase 10
A111: RTM Operations | B111: MD046 | C111: ZUDC | D111: Uyanguren Davao City - FS | E111: Mindanao 1 | F111: Jordan Falcon | G111: 639176341749 | H111: =VLOOKUP(C111,Stores!$A$200:$G$1118,3,0) -> #N/A | I111: =VLOOKUP(C111,Stores!$A$200:$G$1118,4,0) -> #N/A | J111: =VLOOKUP(C111,Stores!$A$200:$G$1118,5,0) -> #N/A | K111: =VLOOKUP(C111,Stores!$A$200:$G$1118,6,0) -> #N/A | L111: =VLOOKUP(C111,Stores!$A$200:$G$1118,7,0) -> #N/A | M111: Phase 10
A112: RTM Operations | B112: MA024 | C112: GGCA | D112: Gaisano Grand Cabadbaran | E112: Mindanao 2 | F112: Jayson Gamayon | G112: 9285202534 | H112: =VLOOKUP(C112,Stores!$A$200:$G$1118,3,0) -> #N/A | I112: =VLOOKUP(C112,Stores!$A$200:$G$1118,4,0) -> #N/A | J112: =VLOOKUP(C112,Stores!$A$200:$G$1118,5,0) -> #N/A | K112: =VLOOKUP(C112,Stores!$A$200:$G$1118,6,0) -> #N/A | L112: =VLOOKUP(C112,Stores!$A$200:$G$1118,7,0) -> #N/A | M112: Phase 10
A113: RTM Operations | B113: MA021 | C113: GSBT | D113: Gaisano Butuan | E113: Mindanao 2 | F113: Johnny Coronel | G113: 9563287387 | H113: =VLOOKUP(C113,Stores!$A$200:$G$1118,3,0) -> #N/A | I113: =VLOOKUP(C113,Stores!$A$200:$G$1118,4,0) -> #N/A | J113: =VLOOKUP(C113,Stores!$A$200:$G$1118,5,0) -> #N/A | K113: =VLOOKUP(C113,Stores!$A$200:$G$1118,6,0) -> #N/A | L113: =VLOOKUP(C113,Stores!$A$200:$G$1118,7,0) -> #N/A | M113: Phase 10
... A121: RTM Operations | B121: MT001 | C121: ZWAO | D121: Wao - FS | E121: Mindanao 2 | F121: Narciso Cordova | G121: 9278684106 | H121: =VLOOKUP(C121,Stores!$A$200:$G$1118,3,0) -> #N/A | I121: =VLOOKUP(C121,Stores!$A$200:$G$1118,4,0) -> #N/A | J121: =VLOOKUP(C121,Stores!$A$200:$G$1118,5,0) -> #N/A | K121: =VLOOKUP(C121,Stores!$A$200:$G$1118,6,0) -> #N/A | L121: =VLOOKUP(C121,Stores!$A$200:$G$1118,7,0) -> #N/A | M121: Phase 10
A122: RTM Operations | B122: MO060 | C122: ZBCO | D122: Bulua Cagayan de Oro-FS | E122: Mindanao 2 | H122: =VLOOKUP(C122,Stores!$A$200:$G$1118,3,0) -> #N/A | I122: =VLOOKUP(C122,Stores!$A$200:$G$1118,4,0) -> #N/A | J122: =VLOOKUP(C122,Stores!$A$200:$G$1118,5,0) -> #N/A | K122: =VLOOKUP(C122,Stores!$A$200:$G$1118,6,0) -> #N/A | L122: =VLOOKUP(C122,Stores!$A$200:$G$1118,7,0) -> #N/A | M122: Phase 10
A123: RTM Operations | B123: NN059 | C123: AY30 | D123: Ayala Mall 30th | E123: NCR North & East | H123: =VLOOKUP(C123,Stores!$A$200:$G$1118,3,0) -> #N/A | I123: =VLOOKUP(C123,Stores!$A$200:$G$1118,4,0) -> #N/A | J123: =VLOOKUP(C123,Stores!$A$200:$G$1118,5,0) -> #N/A | K123: =VLOOKUP(C123,Stores!$A$200:$G$1118,6,0) -> #N/A | L123: =VLOOKUP(C123,Stores!$A$200:$G$1118,7,0) -> #N/A | M123: Phase 10
A124: RTM Operations | B124: CG003 | C124: IAPL | D124: iMall Antipolo | E124: NCR North & East | H124: =VLOOKUP(C124,Stores!$A$200:$G$1118,3,0) -> #N/A | I124: =VLOOKUP(C124,Stores!$A$200:$G$1118,4,0) -> #N/A | J124: =VLOOKUP(C124,Stores!$A$200:$G$1118,5,0) -> #N/A | K124: =VLOOKUP(C124,Stores!$A$200:$G$1118,6,0) -> #N/A | L124: =VLOOKUP(C124,Stores!$A$200:$G$1118,7,0) -> #N/A | M124: Phase 10
A125: RTM Operations | B125: CG129 | C125: MSMT | D125: Massway Mall Tanay | E125: NCR North & East | H125: =VLOOKUP(C125,Stores!$A$200:$G$1118,3,0) -> #N/A | I125: =VLOOKUP(C125,Stores!$A$200:$G$1118,4,0) -> #N/A | J125: =VLOOKUP(C125,Stores!$A$200:$G$1118,5,0) -> #N/A | K125: =VLOOKUP(C125,Stores!$A$200:$G$1118,6,0) -> #N/A | L125: =VLOOKUP(C125,Stores!$A$200:$G$1118,7,0) -> #N/A | M125: Phase 10
A126: RTM Operations | B126: CG140 | C126: PGTT | D126: Puregold Taytay | E126: NCR North & East | H126: =VLOOKUP(C126,Stores!$A$200:$G$1118,3,0) -> #N/A | I126: =VLOOKUP(C126,Stores!$A$200:$G$1118,4,0) -> #N/A | J126: =VLOOKUP(C126,Stores!$A$200:$G$1118,5,0) -> #N/A | K126: =VLOOKUP(C126,Stores!$A$200:$G$1118,6,0) -> #N/A | L126: =VLOOKUP(C126,Stores!$A$200:$G$1118,7,0) -> #N/A | M126: Phase 10
A127: RTM Operations | B127: CG125 | C127: SMHA | D127: SM Hypermarket Antipolo | E127: NCR North & East | H127: =VLOOKUP(C127,Stores!$A$200:$G$1118,3,0) -> #N/A | I127: =VLOOKUP(C127,Stores!$A$200:$G$1118,4,0) -> #N/A | J127: =VLOOKUP(C127,Stores!$A$200:$G$1118,5,0) -> #N/A | K127: =VLOOKUP(C127,Stores!$A$200:$G$1118,6,0) -> #N/A | L127: =VLOOKUP(C127,Stores!$A$200:$G$1118,7,0) -> #N/A | M127: Phase 10
A128: RTM Operations | B128: TNN01 | C128: TAFLZ | D128: Ayala Feliz (Mr TOY) | E128: NCR North & East | H128: =VLOOKUP(C128,Stores!$A$200:$G$1118,3,0) -> #N/A | I128: =VLOOKUP(C128,Stores!$A$200:$G$1118,4,0) -> #N/A | J128: =VLOOKUP(C128,Stores!$A$200:$G$1118,5,0) -> #N/A | K128: =VLOOKUP(C128,Stores!$A$200:$G$1118,6,0) -> #N/A | L128: =VLOOKUP(C128,Stores!$A$200:$G$1118,7,0) -> #N/A | M128: Phase 10
A129: RTM Operations | B129: TNN03 | C129: TAMRK | D129: Ayala Marikina (Mr TOY) | E129: NCR North & East | H129: =VLOOKUP(C129,Stores!$A$200:$G$1118,3,0) -> #N/A | I129: =VLOOKUP(C129,Stores!$A$200:$G$1118,4,0) -> #N/A | J129: =VLOOKUP(C129,Stores!$A$200:$G$1118,5,0) -> #N/A | K129: =VLOOKUP(C129,Stores!$A$200:$G$1118,6,0) -> #N/A | L129: =VLOOKUP(C129,Stores!$A$200:$G$1118,7,0) -> #N/A | M129: Phase 10
A130: RTM Operations | B130: TCG01 | C130: TSLUC | D130: Sta. Lucia (Mr TOY) | E130: NCR North & East | H130: =VLOOKUP(C130,Stores!$A$200:$G$1118,3,0) -> #N/A | I130: =VLOOKUP(C130,Stores!$A$200:$G$1118,4,0) -> #N/A | J130: =VLOOKUP(C130,Stores!$A$200:$G$1118,5,0) -> #N/A | K130: =VLOOKUP(C130,Stores!$A$200:$G$1118,6,0) -> #N/A | L130: =VLOOKUP(C130,Stores!$A$200:$G$1118,7,0) -> #N/A | M130: Phase 10
A131: RTM Operations | B131: CG099 | C131: XROD | D131: Xentromall Rodriguez | E131: NCR North & East | H131: =VLOOKUP(C131,Stores!$A$200:$G$1118,3,0) -> #N/A | I131: =VLOOKUP(C131,Stores!$A$200:$G$1118,4,0) -> #N/A | J131: =VLOOKUP(C131,Stores!$A$200:$G$1118,5,0) -> #N/A | K131: =VLOOKUP(C131,Stores!$A$200:$G$1118,6,0) -> #N/A | L131: =VLOOKUP(C131,Stores!$A$200:$G$1118,7,0) -> #N/A | M131: Phase 10
A132: RTM Operations | B132: NN080 | C132: ZMGT | D132: Manggahan Pasig - FS | E132: NCR North & East | H132: =VLOOKUP(C132,Stores!$A$200:$G$1118,3,0) -> #N/A | I132: =VLOOKUP(C132,Stores!$A$200:$G$1118,4,0) -> #N/A | J132: =VLOOKUP(C132,Stores!$A$200:$G$1118,5,0) -> #N/A | K132: =VLOOKUP(C132,Stores!$A$200:$G$1118,6,0) -> #N/A | L132: =VLOOKUP(C132,Stores!$A$200:$G$1118,7,0) -> #N/A | M132: Phase 10
A133: RTM Operations | B133: CG096 | C133: CMAB | D133: Citymall Anabu | E133: NCR South & CALAPA | H133: =VLOOKUP(C133,Stores!$A$200:$G$1118,3,0) -> #N/A | I133: =VLOOKUP(C133,Stores!$A$200:$G$1118,4,0) -> #N/A | J133: =VLOOKUP(C133,Stores!$A$200:$G$1118,5,0) -> #N/A | K133: =VLOOKUP(C133,Stores!$A$200:$G$1118,6,0) -> #N/A | L133: =VLOOKUP(C133,Stores!$A$200:$G$1118,7,0) -> #N/A | M133: Phase 10
... A577: RTM Operations | B577: VW007 | C577: SCDZ | D577: SM Hypermarket Cadiz | E577: Visayas 1 | H577: =VLOOKUP(C577,Stores!$A$200:$G$1118,3,0) -> Opened Stores | I577: =VLOOKUP(C577,Stores!$A$200:$G$1118,4,0) -> Stage 7 - Installed | J577: =VLOOKUP(C577,Stores!$A$200:$G$1118,5,0) -> FINGERTEC | K577: =VLOOKUP(C577,Stores!$A$200:$G$1118,6,0) -> 7420086 | L577: =VLOOKUP(C577,Stores!$A$200:$G$1118,7,0) -> 192.168.1.201 | M577: Phase 6
...

Sheet Summary of Roll Out Phase
F1: Roll Out Phase | G1: Cluster | H1: No. of Stores | I1: Date | J1: Remarks
F2: Phase 1 | G2: NCR North & East | H2: 100 | I2: 46158
F3: Phase 2 | G3: NCR North & East | H3: 9
G4: NCR South & CALAPA | H4: 80
G5: North & Central Luzon | H5: 11
F6: Phase 3 | G6: North & Central Luzon | H6: 100
F7: Phase 4 | G7: North & Central Luzon | H7: 66
G8: South Luzon | H8: 34
F9: Phase 5 | G9: South Luzon | H9: 68
G10: Visayas 1 | H10: 32
F11: Phase 6 | G11: Visayas 1 | H11: 97
G12: Visayas 2 | H12: 3
F13: Phase 7 | G13: Mindanao 1 | H13: 15
G14: Visayas 2 | H14: 85
F15: Phase 8 | G15: Mindanao 1 | H15: 84
G16: Mindanao 2 | H16: 16
F17: Phase 9 | G17: Mindanao 2 | H17: 108
F18: Phase 10 | G18: Mindanao 1 | H18: 10 | J18: Tagged as no internet yet
G19: Mindanao 2 | H19: 11
G20: NCR North & East | H20: 10
G21: NCR South & CALAPA | H21: 10
G22: North & Central Luzon | H22: 6
G23: South Luzon | H23: 3
G24: Visayas 1 | H24: 9
G25: Visayas 2 | H25: 7
